{"trial_id": "041", "hyperparameters": {"space": [{"class_name": "Int", "config": {"name": "conv_1_filters", "default": null, "conditions": [], "min_value": 32, "max_value": 256, "step": 32, "sampling": "linear"}}, {"class_name": "Int", "config": {"name": "conv_2_filters", "default": null, "conditions": [], "min_value": 32, "max_value": 128, "step": 32, "sampling": "linear"}}, {"class_name": "Int", "config": {"name": "conv_3_filters", "default": null, "conditions": [], "min_value": 32, "max_value": 64, "step": 16, "sampling": "linear"}}, {"class_name": "Int", "config": {"name": "dense_units", "default": null, "conditions": [], "min_value": 64, "max_value": 256, "step": 64, "sampling": "linear"}}, {"class_name": "Float", "config": {"name": "learning_rate", "default": 0.0001, "conditions": [], "min_value": 0.0001, "max_value": 0.01, "step": null, "sampling": "log"}}, {"class_name": "Choice", "config": {"name": "activation", "default": "relu", "conditions": [], "values": ["relu", "tanh", "sigmoid"], "ordered": false}}], "values": {"conv_1_filters": 160, "conv_2_filters": 32, "conv_3_filters": 32, "dense_units": 256, "learning_rate": 0.0001, "activation": "sigmoid"}}, "metrics": {"metrics": {"accuracy": {"direction": "max", "observations": [{"value": [0.6346388459205627], "step": 0}]}, "loss": {"direction": "min", "observations": [{"value": [1.3060470819473267], "step": 0}]}, "val_accuracy": {"direction": "max", "observations": [{"value": [0.6696606874465942], "step": 0}]}, "val_loss": {"direction": "min", "observations": [{"value": [1.1368378400802612], "step": 0}]}}}, "score": 0.6696606874465942, "best_step": 0, "status": "FAILED", "message": "Traceback (most recent call last):\n  File \"/home/bosa/manu2/manu/.venv/lib/python3.10/site-packages/keras_tuner/src/engine/base_tuner.py\", line 274, in _try_run_and_update_trial\n    self._run_and_update_trial(trial, *fit_args, **fit_kwargs)\n  File \"/home/bosa/manu2/manu/.venv/lib/python3.10/site-packages/keras_tuner/src/engine/base_tuner.py\", line 239, in _run_and_update_trial\n    results = self.run_trial(trial, *fit_args, **fit_kwargs)\n  File \"/home/bosa/manu2/manu/.venv/lib/python3.10/site-packages/keras_tuner/src/engine/tuner.py\", line 314, in run_trial\n    obj_value = self._build_and_fit_model(trial, *args, **copied_kwargs)\n  File \"/home/bosa/manu2/manu/.venv/lib/python3.10/site-packages/keras_tuner/src/engine/tuner.py\", line 233, in _build_and_fit_model\n    results = self.hypermodel.fit(hp, model, *args, **kwargs)\n  File \"/home/bosa/manu2/manu/.venv/lib/python3.10/site-packages/keras_tuner/src/engine/hypermodel.py\", line 149, in fit\n    return model.fit(*args, **kwargs)\n  File \"/home/bosa/manu2/manu/.venv/lib/python3.10/site-packages/keras/src/utils/traceback_utils.py\", line 122, in error_handler\n    raise e.with_traceback(filtered_tb) from None\n  File \"/home/bosa/manu2/manu/.venv/lib/python3.10/site-packages/tensorflow/python/eager/execute.py\", line 53, in quick_execute\n    tensors = pywrap_tfe.TFE_Py_Execute(ctx._handle, device_name, op_name,\ntensorflow.python.framework.errors_impl.InternalError: Graph execution error:\n\nDetected at node StatefulPartitionedCall defined at (most recent call last):\n  File \"/usr/lib/python3.10/runpy.py\", line 196, in _run_module_as_main\n\n  File \"/usr/lib/python3.10/runpy.py\", line 86, in _run_code\n\n  File \"/home/bosa/manu2/manu/.venv/lib/python3.10/site-packages/ipykernel_launcher.py\", line 18, in <module>\n\n  File \"/home/bosa/manu2/manu/.venv/lib/python3.10/site-packages/traitlets/config/application.py\", line 1075, in launch_instance\n\n  File \"/home/bosa/manu2/manu/.venv/lib/python3.10/site-packages/ipykernel/kernelapp.py\", line 739, in start\n\n  File \"/home/bosa/manu2/manu/.venv/lib/python3.10/site-packages/tornado/platform/asyncio.py\", line 205, in start\n\n  File \"/usr/lib/python3.10/asyncio/base_events.py\", line 603, in run_forever\n\n  File \"/usr/lib/python3.10/asyncio/base_events.py\", line 1909, in _run_once\n\n  File \"/usr/lib/python3.10/asyncio/events.py\", line 80, in _run\n\n  File \"/home/bosa/manu2/manu/.venv/lib/python3.10/site-packages/ipykernel/kernelbase.py\", line 545, in dispatch_queue\n\n  File \"/home/bosa/manu2/manu/.venv/lib/python3.10/site-packages/ipykernel/kernelbase.py\", line 534, in process_one\n\n  File \"/home/bosa/manu2/manu/.venv/lib/python3.10/site-packages/ipykernel/kernelbase.py\", line 437, in dispatch_shell\n\n  File \"/home/bosa/manu2/manu/.venv/lib/python3.10/site-packages/ipykernel/ipkernel.py\", line 362, in execute_request\n\n  File \"/home/bosa/manu2/manu/.venv/lib/python3.10/site-packages/ipykernel/kernelbase.py\", line 778, in execute_request\n\n  File \"/home/bosa/manu2/manu/.venv/lib/python3.10/site-packages/ipykernel/ipkernel.py\", line 449, in do_execute\n\n  File \"/home/bosa/manu2/manu/.venv/lib/python3.10/site-packages/ipykernel/zmqshell.py\", line 549, in run_cell\n\n  File \"/home/bosa/manu2/manu/.venv/lib/python3.10/site-packages/IPython/core/interactiveshell.py\", line 3075, in run_cell\n\n  File \"/home/bosa/manu2/manu/.venv/lib/python3.10/site-packages/IPython/core/interactiveshell.py\", line 3130, in _run_cell\n\n  File \"/home/bosa/manu2/manu/.venv/lib/python3.10/site-packages/IPython/core/async_helpers.py\", line 128, in _pseudo_sync_runner\n\n  File \"/home/bosa/manu2/manu/.venv/lib/python3.10/site-packages/IPython/core/interactiveshell.py\", line 3334, in run_cell_async\n\n  File \"/home/bosa/manu2/manu/.venv/lib/python3.10/site-packages/IPython/core/interactiveshell.py\", line 3517, in run_ast_nodes\n\n  File \"/home/bosa/manu2/manu/.venv/lib/python3.10/site-packages/IPython/core/interactiveshell.py\", line 3577, in run_code\n\n  File \"/tmp/ipykernel_5505/3701750037.py\", line 1, in <module>\n\n  File \"/home/bosa/manu2/manu/.venv/lib/python3.10/site-packages/keras_tuner/src/engine/base_tuner.py\", line 234, in search\n\n  File \"/home/bosa/manu2/manu/.venv/lib/python3.10/site-packages/keras_tuner/src/engine/base_tuner.py\", line 274, in _try_run_and_update_trial\n\n  File \"/home/bosa/manu2/manu/.venv/lib/python3.10/site-packages/keras_tuner/src/engine/base_tuner.py\", line 239, in _run_and_update_trial\n\n  File \"/home/bosa/manu2/manu/.venv/lib/python3.10/site-packages/keras_tuner/src/engine/tuner.py\", line 314, in run_trial\n\n  File \"/home/bosa/manu2/manu/.venv/lib/python3.10/site-packages/keras_tuner/src/engine/tuner.py\", line 233, in _build_and_fit_model\n\n  File \"/home/bosa/manu2/manu/.venv/lib/python3.10/site-packages/keras_tuner/src/engine/hypermodel.py\", line 149, in fit\n\n  File \"/home/bosa/manu2/manu/.venv/lib/python3.10/site-packages/keras/src/utils/traceback_utils.py\", line 117, in error_handler\n\n  File \"/home/bosa/manu2/manu/.venv/lib/python3.10/site-packages/keras/src/backend/tensorflow/trainer.py\", line 320, in fit\n\n  File \"/home/bosa/manu2/manu/.venv/lib/python3.10/site-packages/keras/src/backend/tensorflow/trainer.py\", line 121, in one_step_on_iterator\n\nFailed to initialize BLAS support\n\t [[{{node StatefulPartitionedCall}}]] [Op:__inference_one_step_on_iterator_2241]\n"}